Workbook

Sheet Cover
B12: Effective from 15th June 2026
B14: Contact Details
B15: General | C15: Info@alpinetradeblinds.com
B16: Orders | C16: Sales@alpinetradeblinds.com
B17: Issues | C17: Issues@alpinetradeblinds.com
B18: Spares | C18: Spares@alpinetradeblinds.com
B19: Online Portal | C19: Blindata Online
B20: Phone | C20: 0161 4 500 500
B21: Mobile/wattsapp | C21: 07933150545
B23: Credit Team | C23: accounts@alpinetradeblinds.com
B24: Mobile - whatsapp | D24: 077461709664
B26: Office Opening Hours
B27: Monday - Friday 9am - 4.30pm
B30: Orders below £400 ex vat will incur £20 delivery charge

Sheet Terms & Conditions
B2: ALPINE TRADE BLINDS LIMITED – TERMS & CONDITIONS
B4: 1. ACCEPTANCE OF TERMS
B5: • By placing an order, requesting a quotation, purchasing goods, making payment, opening a trade account, accessing pricing information, accepting delivery, or using any products or services supplied by Alpine Trade Blinds Limited, the customer confirms that they have read, understood, and accepted these Terms & Conditions in full.
B6: • These Terms & Conditions apply to all quotations, orders, sales, deliveries, products, services, installations, repairs, warranties, and any other dealings between Alpine Trade Blinds Limited and the customer unless otherwise agreed in writing by a Director of Alpine Trade Blinds Limited.
B7: • No variation to these Terms & Conditions shall be binding unless confirmed in writing by Alpine Trade Blinds Limited.
B9: 2. TRADE ONLY
B10: All prices, quotations, products, and services are supplied strictly to trade customers unless otherwise agreed in writing.
B12: 3. GENERAL
B13: All orders placed with Alpine Trade Blinds Limited are subject to these Terms & Conditions.
B14: The customer's submission of an order, acceptance of a quotation, payment of an invoice, acceptance of delivery, or use of any products or services supplied by Alpine Trade Blinds Limited shall constitute full acceptance of these Terms & Conditions.
B15: Where a customer provides a purchase order or their own terms and conditions, Alpine Trade Blinds Limited's Terms & Conditions shall prevail unless otherwise agreed in writing.
B17: 4. PRICING
... B155: OL1 3NL

Sheet Master Control
B2: Company Name | C2: Start Date
B3: Shades and Space | C3: 15.06.2026
I4: Max Width | J4: Max width
B5: Master Control | E5: Fabric Search | F5: Design | G5: Band | H5: Type | I5: mm | J5: inches | K5: Supplier | L5: Book | M5: Comments
B6: Discount is for Blind only and not any extras | E6: type here | F6: {=_xlfn._xlws.FILTER('Fabric Library'!B3:I891,IFERROR(ISNUMBER(SEARCH($E$6,'Fabric Library'!B3:B891)),FALSE),"NO RESULTS")} -> NO RESULTS
B7: Product | C7: Discount
B8: 127mm Vertical | C8: 0
B9: 25mm Aluminium | C9: 0.25
B10: 3BS Pleated | C10: 0.25
B11: 89mm Vertical | C11: 0.35
B12: Allusion | C12: 0.2
B13: Aquawood Fauxwood | C13: 0.25
B14: Essence Fauxwood | C14: 0.25
B15: Expressions Fauxwood | C15: 0.25
B16: Freehang Pleated | C16: 0.25
B17: Nightshade | C17: 0.2
B18: Perfect Fit Aluminium | C18: 0.25
B19: Perfect Fit Pleated | C19: 0.25
... B36: Fit to Frame Pleated | C36: 0

Sheet Fabric Library
B2: Design | C2: Band | D2: Type | E2: Max width - mm | F2: Max width - inches | G2: Supplier | H2: Book | I2: Comments
B3: Acacia | C3: C | D3: Roller | E3: 2000 | F3: =MROUND(E3/25.4,1/8) -> 78.75 | G3: Louvolite
B4: Ada | C4: A | D4: 89mm | E4: 89 | F4: =MROUND(E4/25.4,1/8) -> 3.5 | G4: Arena
B5: Ada | C5: B | D5: Roller | E5: 2000 | F5: =MROUND(E5/25.4,1/8) -> 78.75 | G5: Arena
B6: Ada | C6: B | D6: 89mm | E6: 89 | F6: =MROUND(E6/25.4,1/8) -> 3.5 | G6: Eclipse | H6: Market Collection
B7: Ada | C7: B | D7: Roller | E7: 2000 | F7: =MROUND(E7/25.4,1/8) -> 78.75 | G7: Eclipse | H7: Market Collection
B8: Aki (Not Available) | C8: F | D8: Roller | E8: 2800 | F8: =MROUND(E8/25.4,1/8) -> 110.25 | G8: Decora | H8: Fabric Box | I8: Fabric Not available - too many issues
B9: Akita | C9: C | D9: Roller | E9: 2000 | F9: =MROUND(E9/25.4,1/8) -> 78.75 | G9: Decora | H9: Fabric Box
B10: Akita Blackout | C10: D | D10: Roller | E10: 2000 | F10: =MROUND(E10/25.4,1/8) -> 78.75 | G10: Decora | H10: Fabric Box
B11: Alara | C11: E | D11: Roller | E11: 2400 | F11: =MROUND(E11/25.4,1/8) -> 94.5 | G11: Decora | H11: Fabric Box
B12: Alara | C12: E | D12: 89mm | E12: 89 | F12: =MROUND(E12/25.4,1/8) -> 3.5 | G12: Decora | H12: Fabric Box
B13: Albero | C13: D | D13: Vision | E13: 2800 | F13: =MROUND(E13/25.4,1/8) -> 110.25 | G13: Louvolite
B14: Alessi | C14: B | D14: Roller | E14: 2000 | F14: =MROUND(E14/25.4,1/8) -> 78.75 | G14: Decora | H14: Fabric Box | I14: Discontinued
B15: Alessi | C15: B | D15: 89mm | E15: 89 | F15: =MROUND(E15/25.4,1/8) -> 3.5 | G15: Decora | H15: Fabric Box | I15: Discontinued
B16: Algarve | C16: E | D16: Roller | E16: 2000 | F16: =MROUND(E16/25.4,1/8) -> 78.75 | G16: Eclipse
B17: Allegria | C17: C | D17: Vision | E17: 2800 | F17: =MROUND(E17/25.4,1/8) -> 110.25 | G17: Louvolite
B18: Allure | C18: D | D18: Vision | E18: 2800 | F18: =MROUND(E18/25.4,1/8) -> 110.25 | G18: Eclipse | H18: Mirage
B19: Alta | C19: C | D19: Roller | E19: 2000 | F19: =MROUND(E19/25.4,1/8) -> 78.75 | G19: Arena
B20: Alta | C20: C | D20: Roller | E20: 2000 | F20: =MROUND(E20/25.4,1/8) -> 78.75 | G20: Eclipse
B21: Alta Blackout | C21: E | D21: Roller | E21: 2000 | F21: =MROUND(E21/25.4,1/8) -> 78.75 | G21: Eclipse
B22: Alta Blackout | C22: E | D22: Roller | E22: 2000 | F22: =MROUND(E22/25.4,1/8) -> 78.75 | G22: Arena
B23: Altea | C23: C | D23: Roller | E23: 2000 | F23: =MROUND(E23/25.4,1/8) -> 78.75 | G23: Decora | H23: Fabric Box
B24: Altea | C24: D | D24: 89mm | E24: 89 | F24: =MROUND(E24/25.4,1/8) -> 3.5 | G24: Decora | H24: Fabric Box
B25: Alvor | C25: D | D25: Roller | E25: 2000 | F25: =MROUND(E25/25.4,1/8) -> 78.75 | G25: Decora | H25: Fabric Box
B26: Alvor | C26: E | D26: 89mm | E26: 89 | F26: =MROUND(E26/25.4,1/8) -> 3.5 | G26: Decora | H26: Fabric Box
B27: Amaris | C27: AA | D27: Roller | E27: 2000 | F27: =MROUND(E27/25.4,1/8) -> 78.75 | G27: Decora | H27: Excel
B28: Amaris | C28: AA | D28: 89mm | E28: 89 | F28: =MROUND(E28/25.4,1/8) -> 3.5 | G28: Decora | H28: Excel
B29: Amberley | C29: AA | D29: 89mm | E29: 89 | F29: =MROUND(E29/25.4,1/8) -> 3.5 | G29: Alutrade
B30: Amico | C30: C | D30: Roller | E30: 2400 | F30: =MROUND(E30/25.4,1/8) -> 94.5 | G30: Decora | H30: Fabric Box
B31: Argent N/A | C31: F | D31: 89mm | E31: 89 | F31: =MROUND(E31/25.4,1/8) -> 3.5 | G31: Louvolite | I31: Not Available
B32: Argent N/A | C32: E | D32: Roller | E32: 2000 | F32: =MROUND(E32/25.4,1/8) -> 78.75 | G32: Louvolite | I32: Not Available
B33: Argento | C33: NA | D33: Vision | E33: NA | F33: NA | G33: Louvolite | I33: Discontinued
B34: Aria | C34: B | D34: 89mm | E34: 89 | F34: =MROUND(E34/25.4,1/8) -> 3.5 | G34: Decora | H34: Fabric Box
B35: Ariana | C35: A | D35: 89mm | E35: 89 | F35: =MROUND(E35/25.4,1/8) -> 3.5 | G35: Eclipse | H35: Market Collection
B36: Ariana | C36: A | D36: Roller | E36: 2000 | F36: =MROUND(E36/25.4,1/8) -> 78.75 | G36: Eclipse | H36: Market Collection
B37: Ariel | C37: B | D37: 89mm | E37: 89 | F37: =MROUND(E37/25.4,1/8) -> 3.5 | G37: Alutrade
B38: Ariel | C38: B | D38: Roller | E38: 1830 | F38: =MROUND(E38/25.4,1/8) -> 72 | G38: Alutrade
B39: Arona | C39: C | D39: Roller | E39: 2400 | F39: =MROUND(E39/25.4,1/8) -> 94.5 | G39: Decora | H39: Fabric Box
B40: Arona | C40: C | D40: 89mm | E40: 89 | F40: =MROUND(E40/25.4,1/8) -> 3.5 | G40: Decora | H40: Fabric Box
B41: Arrezzo | C41: B | D41: Vision | E41: 2800 | F41: =MROUND(E41/25.4,1/8) -> 110.25 | G41: Louvolite
...

Sheet Fabric Box 2025
B1: DECORA 2026
B2: Fabrics that are highlighted in Red are now discontinued
B3: Roller | E3: Roller | H3: EXCEL ROLLER | K3: Vertical | N3: 127MM | O3: Name | P3: Band
B4: Name | C4: Band | E4: Name | F4: Band | H4: Fabric | I4: Band | K4: Name | L4: Band | N4: Decora | O4: Barclay | P4: C
B5: Aki (Not available) | C5: F | E5: Mezza | F5: D | H5: Amaris | I5: AA | K5: Alara | L5: E | N5: Decora | O5: Bella | P5: B
B6: Akita | C6: C | E6: Midas | F6: F | H6: Cleo | I6: AA | K6: Altea | L6: D | N6: Decora | O6: Glimpse | P6: C
B7: Akita Blackout | C7: D | E7: Miro | F7: C | H7: Fiesta | I7: AA | K7: Alessi | L7: B | N7: Decora | O7: Hayden | P7: B
B8: Alara | C8: E | E8: Miro Blackout | F8: D | H8: Java | I8: AA | K8: Alvor | L8: E | N8: Decora | O8: Hayworth | P8: C
B9: Alessi | C9: B | E9: Mood | F9: A | H9: Kira | I9: AA | K9: Aria | L9: B | N9: Decora | O9: Rocha | P9: D
B10: Altea | C10: C | E10: Moxie | F10: C | H10: Malimo | I10: AA | K10: Arona | L10: C | N10: Decora | O10: Soma | P10: D
B11: Alvor | C11: D | E11: Musa | F11: B | H11: Monarch | I11: AA | K11: Barclay | L11: B | N11: Decora | O11: Splash | P11: A
B12: Amico | C12: C | E12: Myth | F12: C | H12: Opus | I12: AA | K12: Bella 89 OR 127 | L12: B | N12: Decora | O12: Unicolour | P12: B
B13: Arona | C13: C | E13: Napa | F13: C | H13: Verona | I13: AA | K13: Bexley | L13: C | N13: Decora | O13: Uniline | P13: A
B14: Barclay | C14: C | E14: Odin | F14: D | H14: Zara | I14: AA | K14: Como | L14: A | N14: Decora | O14: Unishade | P14: C
B15: Bella | C15: B | E15: Orissa | F15: C | K15: Devon | L15: C
B16: Bexley | C16: C | E16: Plaza | F16: B | K16: Diva | L16: B | N16: Softshade - Vision
B17: Boheme | C17: B | E17: Puriti | F17: C | H17: EXCEL 89mm | K17: Ennis | L17: C | N17: Fabric | O17: Band | P17: Max Width
B18: Boho | C18: C | E18: Renzo | F18: C | H18: Fabric | I18: Band | K18: Estella | L18: D | N18: Luna | O18: A | P18: 3000
B19: Botany | C19: C | E19: Rocha | F19: E | H19: Amaris | I19: AA | K19: Fleur | L19: B | N19: Nobis | O19: D | P19: 2600
B20: Calista | C20: D | E20: Sabina | F20: E | H20: Cameo | I20: AA | K20: Glimpse | L20: C | N20: Kanza | O20: D | P20: 3000
B21: Como | C21: A | E21: Sahara | F21: B | H21: Carlo | I21: AA | K21: Hayden | L21: B | N21: Rift | O21: B | P21: 2800
B22: Devon | C22: C | E22: Samba | F22: B | H22: Cleo | I22: AA | K22: Hayworth | L22: C | N22: Mero | O22: E | P22: 2800
B23: Dino | C23: D | E23: Sasha | F23: B | H23: Dalia | I23: AA | K23: Hanson | L23: E | N23: Rosso | O23: C | P23: 2800
B24: Diva | C24: B | E24: Scope | F24: A | H24: Fiesta | I24: AA | K24: Henlow | L24: C | N24: Tela | O24: E | P24: 2800
B25: Dollie | C25: D | E25: Semana | F25: C | H25: Java | I25: AA | K25: Isla | L25: B | N25: Hoxton | O25: D | P25: 2800
B26: Ducato | C26: E | E26: Sento | F26: D | H26: Kira | I26: AA | K26: Kobe | L26: D
B27: Ella | C27: C | E27: Sephora | F27: D | H27: Fitz | I27: A | K27: Legacy | L27: B
B28: Ella Blackout | C28: D | E28: Sephora Blackout | F28: D | H28: Lana | I28: AA | K28: Luxari | L28: B
B29: Ennis | C29: C | E29: Serena | F29: B | H29: Lucca BO | I29: A | K29: Linden | L29: D
B30: Estella | C30: C | E30: Serra | F30: C | H30: Malimo | I30: AA | K30: Renzo | L30: C
B31: Flock | C31: C | E31: Shima | F31: B | H31: Mia | I31: AA | K31: Medina | L31: B
B32: Focal (Not available) | C32: F | E32: Sio | F32: C | H32: Monarch | I32: AA | K32: Metz | L32: B
B33: Glimpse | C33: D | E33: Sirocco | F33: B | H33: Opus | I33: AA | K33: Mood | L33: B
B34: Halo | C34: A | E34: Sisi | F34: C | H34: Rossini | I34: AA | K34: Myth | L34: C
B35: Hanson | C35: D | E35: Solice | F35: C | H35: Senna | I35: AA | K35: Nera | L35: B
B36: Hayden | C36: C | E36: Soma | F36: D | H36: Zara | I36: AA | K36: Odin | L36: D
B37: Hayworth | C37: D | E37: Sora | F37: C | H37: Verona | I37: AA | K37: Orissa | L37: D
B38: Henlow | C38: C | E38: Sorenza | F38: C | K38: Plaza | L38: B
B39: Honor | C39: C | E39: Splash | F39: A | H39: PVC 89mm | K39: Renzo | L39: C
B40: Isla | C40: B | E40: Splash 3m width | F40: A | K40: Rocha | L40: D
...

Sheet Arena 2026
B1: ARENA FABRIC BANDS 2026
B2: Vertical | C2: Band | E2: Roller | F2: Band | H2: Roller | I2: Band
B3: Ada | C3: A | E3: Ada | F3: B | H3: Monte Blackout | I3: E
B4: Aspen | C4: C | E4: Alta | F4: C | H4: Nordic asc | I4: D
B5: Astratto | C5: A | E5: Alta Blackout | F5: E | H5: Oakley | I5: B
B6: Atlantex | C6: B | E6: Artisan | F6: E | H6: Ocean Crmson or Taupe | I6: E
B7: Bamboo | C7: A | E7: Aspen | F7: D | H7: Odessa | I7: B
B8: Banlight Duo Fr | C8: C | E8: Athena | F8: D | H8: Odin | I8: D
B9: Bliss | C9: B | E9: Atlantex | F9: B | H9: Ombre | I9: D
B10: Boston Fr | C10: C | E10: Atlantex asc | F10: C | H10: Paige | I10: B
B11: Bounce | C11: E | E11: Autumn | F11: C | H11: Palette Fr | I11: B
B12: Caspian | C12: A | E12: Bamboo | F12: A | H12: Panama Deco 3% | I12: F+15%
B13: Clarice | C13: E | E13: Banlight Duo FR | F13: B | H13: Paris | I13: D
... B51: Shantung | C51: A | E51: Linenweave | F51: B | H51: Zayn | I51: E
B52: Shona | C52: E | E52: Linenweave Blackout | F52: E
B53: Sian | C53: A | E53: Mabel | F53: E
B54: Sisi | C54: E | E54: Maeve | F54: D
B55: Sprigs | C55: E | E55: Maggie | F55: D
B56: Stella fr | C56: B | E56: Magical | F56: E
B57: Stratford | C57: A | E57: Marea | F57: A
B58: Topaz | C58: B | E58: Mariella | F58: C
B59: Traze | C59: B | E59: Maverick | F59: E
B60: Tree of life | C60: E | E60: Melody | F60: E
B61: Urban FR | C61: C | E61: Molina | F61: C
B62: Vinne | C62: C | E62: Monte | F62: C

Sheet Alutrade
B2: Alutrade Fabric Bands 2026
B3: VERTICAL 89mm | E3: VERTICAL 89mm
B4: NAME | C4: Band | E4: NAME | F4: Band
B5: Amberley | C5: AA | E5: Ariel | F5: B
B6: Ariel | C6: B | E6: Atlas | F6: A
B7: Atlas | C7: A | E7: Callisto | F7: B
B8: Breedon | C8: AA | E8: Classic Blackout | F8: A
B9: Broadwell | C9: AA | E9: Classic Dimout | F9: AA
B10: Callisto | C10: B | E10: Europa | F10: B
B11: Campden | C11: AA | E11: Hydra | F11: B
B12: Chilson | C12: AA | E12: Larissa | F12: B
B13: Classic Blackout | C13: A | E13: Metis | F13: B
B14: Classic Dimout | C14: AA | E14: Rhea | F14: B
B15: Derwent | C15: AA | E15: Signature Blackout | F15: A
... B19: Kineton | C19: AA | E19: Triton | F19: B
B20: Kingham | C20: AA
B21: Larissa | C21: B | E21: Name | F21: 127 Band
B22: Leafield | C22: AA | E22: Broadwell | F22: AA
B23: Metis | C23: B | E23: Kineton | F23: AA
B24: Morten | C24: AA | E24: Somerton | F24: AA
B25: Pebworth | C25: AA | E25: Windrush | F25: A
B26: Rhea | C26: B
B27: Rissington | C27: AA
B28: Saintbury | C28: AA
B29: Signature Blackout | C29: A
B30: Signature Dimout | C30: AA
B31: Signature FR Blackout | C31: B
B32: Signature FR Dimout | C32: A
B33: Somerton | C33: AA
B34: Stretton | C34: AA
B35: Taynton | C35: AA
B36: Triton | C36: B
B37: Windrush | C37: AA

Sheet Louvolite 2026
B1: LOUVOLITE 2026
B2: N/A Fabrics are not available
B3: Vertical | E3: Roller | H3: Roller | K3: VISION | O3: ALLUSION
B4: Name | C4: Band | E4: Name | F4: Band | H4: Name | I4: Band | K4: Design | L4: Width | M4: Band | O4: Design | P4: Band
B5: Argent N/A | C5: F | E5: Acacia | F5: C | H5: Monet (Sheer) | I5: C | K5: Albero | L5: 2800 | M5: D | O5: Horizon | P5: A
B6: Bamboo | C6: C | E6: Argent N/A | F6: E | H6: Montego | I6: D | K6: Allegria | L6: 2800 | M6: C | O6: Natural | P6: B
B7: Bora | C7: A | E7: Azalea Blackout | F7: C | H7: Monterey | I7: E | K7: Arrezzo | L7: 2800 | M7: B | O7: Shadow | P7: C
B8: Carnival | C8: C | E8: Bahama | F8: C | H8: Mosiac Blackout | I8: D | K8: Bella | L8: 2800 | M8: D | O8: Vista | P8: B
B9: Carnival Blackout | C9: D | E9: Bamboo | F9: B | H9: Night Night Blackout | I9: E | K9: Boucle | L9: 2800 | M9: D
B10: Chatsworth | C10: C | E10: Birdsong | F10: C | H10: Night Safari Blackout | I10: E | K10: Capri | L10: 2800 | M10: A
B11: Collina Blackout N/A | C11: F+20% | E11: Boleyn Blackout | F11: C | H11: Nordic | I11: C | K11: Ferrara | L11: 2800 | M11: C
B12: Como | C12: D | E12: Bora | F12: A | H12: Nordic Blackout | I12: D | K12: Firenze | L12: 2800 | M12: B
B13: Como Blackout | C13: E | E13: Brighton Stripe BO | F13: C | H13: Ophelia | I13: D | K13: Floreale | L13: 2800 | M13: D
B14: Cotton Flower | C14: E | E14: Bubbles | F14: C | H14: Orchard Blackout N/A | I14: F | K14: Lusso | L14: 2800 | M14: C
B15: Crush BO N/A | C15: F+20% | E15: Bugs Blackout | F15: D | H15: Oslo | I15: F | K15: Modella | L15: 2800 | M15: B
B16: Dapple SPC+ | C16: D | E16: Carnival | F16: B | H16: Oxford | I16: B | K16: Modina | L16: 2800 | M16: C
B17: Daybreak | C17: B | E17: Carnival Blackout | F17: C | H17: Oxford Blackout | I17: C | K17: Naples | L17: 2800 | M17: B
B18: Didsbury Blackout N/A | C18: D | E18: Chatsworth | F18: C | H18: Paradise Palm Blackout | I18: C | K18: Nola | L18: 2800 | M18: B
B19: Dune | C19: C | E19: Cherry Blossom | F19: D | H19: Perspective 1% | I19: C | K19: Nuvola | L19: 2800 | M19: B
B20: Ex Lite | C20: D | E20: Clearguard | F20: B | H20: Perspective 3% | I20: C | K20: Rimini | L20: 2800 | M20: C
... B23: Haven | C23: C | E23: Como Blackout | F23: D | H23: Perspective Aluview | I23: E | K23: Trento | L23: 2800 | M23: B
B24: Haven Blackout | C24: E | E24: Cotton Flower | F24: C | H24: Perspective Blackout | I24: E
B25: Kona | C25: AA | E25: Crush BO N/A | F25: E | H25: Perspective Pureview | I25: C
B26: Kumano Blackout N/A | C26: F | E26: Dhalia Blackout | F26: C | H26: Petal | I26: C
B27: Marble Blackout | C27: E | E27: Daisy Blackout | F27: C | H27: Petal Blackout | I27: C
B28: Matrix Blackout | C28: E | E28: Damask Blackout | F28: E | H28: Planetarium | I28: E | K28: Supplier | L28: Name | M28: 127 Band
B29: Mistral | C29: A | E29: Dapple SPC+ | F29: C | H29: Pop | I29: A | K29: Louvolite | L29: Carnival | M29: C
B30: Monterey N/A | C30: D | E30: Daybreak | F30: A | H30: Pop Blackout | I30: B | K30: Louvolite | L30: Chatsworth | M30: C
B31: Nordic | C31: C | E31: Didsbury Blackout | F31: D | H31: Reverie Blackout | I31: D | K31: Louvolite | L31: Dapple SPC+ | M31: D
B32: Nordic Blackout N/A | C32: E | E32: Dinosaurs | F32: E | H32: Ribble | I32: A | K32: Louvolite | L32: Daybreak | M32: B
B33: Oslo | C33: D | E33: Draper | F33: C | H33: Ribble Blackout | I33: C | K33: Louvolite | L33: Ex-Lite BO | M33: D
B34: Oxford | C34: C | E34: Dune | F34: C | H34: Ritz | I34: C | K34: Louvolite | L34: Guradian | M34: B
B35: Oxford Blackout | C35: D | E35: Dunham Blackout | F35: D | H35: River | I35: A | K35: Louvolite | L35: Hampton | M35: E
B36: Perspective 1% | C36: C | E36: Ex Lite | F36: C | H36: Romany Blackout | I36: D | K36: Louvolite | L36: Monterey | M36: NA
B37: Perspective 3% | C37: C | E37: Fiji | F37: C | H37: Shot Silk Blackout | I37: F | K37: Louvolite | L37: Oslo | M37: D
B38: Perspective 3% White Back | C38: C | E38: Florence Blackout | F38: C | H38: Sirocco | I38: A | K38: Louvolite | L38: Perspective 1% | M38: D
B39: Perspective 5% | C39: C | E39: Flores | F39: C | H39: Stargazer Blackout | I39: C | K39: Louvolite | L39: Perspective 3% | M39: D
... B48: Ribble | C48: C | E48: Kona | F48: A | H48: Voile White | I48: C | K48: Louvolite | L48: Voile | M48: B
B49: Ribble Dimout | C49: D | E49: Kumano Blackout | F49: E | H49: Wild Garden | I49: C
B50: Ritz | C50: C | E50: Lily | F50: D | H50: Willow BO | I50: E
...

Sheet United
A1: UNITED
B4: VERTICAL | E4: VERTICAL | H4: Roller
B5: Budget
B6: Design | C6: Band | E6: Design | F6: Band | H6: Design | I6: Width | J6: Band
B7: Alabama | C7: AA | E7: Aqualush (discontinued) | F7: B | H7: Alexandria | I7: 2500 | J7: D
B8: Atlantic | C8: AA | E8: Aquamar | F8: B | H8: Aqualush (Discontinued) | I8: 1830 | J8: B
B9: Badar | C9: AA | E9: Cairo | F9: B | H9: Aquamar | I9: 1830 | J9: B
B10: Bond | C10: AA | E10: Elena | F10: B | H10: Aspin | I10: 2400 | J10: E
B11: California | C11: AA | E11: Elm | F11: B | H11: Atlantic | I11: 2000 | J11: A
B12: Cloud | C12: AA | E12: Fabian | F12: A | H12: Berry | I12: 2000 | J12: E
B13: Cross Stich | C13: AA | E13: Fiesta | F13: B | H13: Blossom | I13: 2000 | J13: F
B14: Daisy | C14: AA | E14: Gravity | F14: B | H14: Cairo | I14: 2000 | J14: C
B15: Dolphin | C15: AA | E15: Havana | F15: B | H15: California | I15: 2000 | J15: A
B16: Everest | C16: AA | E16: Jaguar | F16: B | H16: Dolphin | I16: 2000 | J16: A
B17: Feather Weave | C17: AA | E17: Jupiter | F17: B | H17: Elena | I17: 1830 | J17: B
B18: Hambook | C18: AA | E18: kia | F18: C | H18: Elm | I18: 2400 | J18: C
... B31: Swallow | C31: AA | E31: Venus | F31: A | H31: Lahore | I31: 1830 | J31: B
B32: Sweet | C32: AA | H32: Lyon | I32: 2500 | J32: D
B33: Unity | C33: AA | H33: Marina | I33: 2000 | J33: A
H34: Milano | I34: 1830 | J34: B
H35: Oasis | I35: 2600 | J35: D
H36: Opera | I36: 2800 | J36: C
H37: Optimum Standard | I37: 2400 | J37: A
H38: Quin | I38: 2400 | J38: F
H39: Radiance | I39: 2400 | J39: E
H40: Rita | I40: 2500 | J40: D
H41: Sweet Blackout | I41: 2300 | J41: E
H42: Sunrise | I42: 2000 | J42: A
H43: Symphony | I43: 2800 | J43: D
H44: Tango | I44: 1830 | J44: B
H45: Unity | I45: 2000 | J45: AA
... H47: Yacht | I47: 2400 | J47: D

Sheet Eclipse 2026
A1: ECLIPSE 2026
B4: VERTICAL | E4: VERTICAL - MARKET COLLECTION | H4: Roller | K4: Roller | N4: ROLLER - MARKET COLLECTION | R4: MIRAGE
B5: NAME | C5: Band | E5: Design | F5: Band | H5: NAME | I5: Band | K5: NAME | L5: Band | N5: Design | O5: Roller Width | P5: Band | R5: Design | S5: Width | T5: Band
B6: ADA | C6: A | E6: Ariana | F6: A | H6: ADA | I6: B | K6: MAGICAL | L6: E | N6: Ariana | O6: 200cm | P6: A | R6: Allure | S6: 280cm | T6: D
B7: ASPEN | C7: C | E7: Astratto | F7: A | H7: ALGARVE | I7: E | K7: MAREA | L7: A | N7: Astratto | O7: 200cm | P7: A | R7: Aura | S7: 270cm | T7: E
B8: ASTRATTO | C8: A | E8: Bamboo | F8: A | H8: ALTA | I8: C | K8: MARIELLA | L8: C | N8: Bamboo | O8: 200cm | P8: A | R8: Balance | S8: 280cm | T8: E + 5%
B9: ATLANTEX | C9: B | E9: Caspian | F9: A | H9: ALTA B/OUT | I9: E | K9: MIYA | L9: B | N9: Blend | O9: 230cm | P9: A | R9: Beam | S9: 270cm | T9: D
B10: ATLANTEX ASC | C10: B | E10: Castilla | F10: A | H10: ASPEN | I10: D | K10: MOLINA | L10: C | N10: Blend BO | O10: 230cm | P10: B | R10: Crackle | S10: 278cm | T10: D
B11: AVELINE | C11: C | E11: Chevron | F11: A | H11: ATLANTEX | I11: B | K11: MONTE | L11: C | N11: Caspian | O11: 200cm | P11: A | R11: Demure | S11: 270cm | T11: E + 10%
B12: BAMBOO | C12: A | E12: Cypress | F12: A | H12: ATLANTEX ASC | I12: C | K12: MONTE B/OUT | L12: E | N12: Castilla | O12: 200cm | P12: A | R12: Desire | S12: 240cm | T12: C
B13: BANLIGHT DUO | C13: C | E13: Deco | F13: AA | H13: AUTUMN | I13: E | K13: NORDIC ASC | L13: D | N13: Chelsea | O13: 198cm | P13: C | R13: Entwine | S13: 240cm | T13: E +20%
B14: BLISS | C14: B | E14: Evita | F14: A | H14: AVELINE | I14: D | K14: OAKLEY | L14: B | N14: Cypress | O14: 200cm | P14: A | R14: Essence | S14: 280cm | T14: A
B15: BOSTON | C15: D | E15: Jordan | F15: A | H15: AXEL | I15: E | K15: ODESSA | L15: B | N15: Evita | O15: 200cm | P15: A | R15: Illume | S15: 280cm | T15: C
B16: BURST | C16: E | E16: Katrine | F16: A | H16: BAMBOO | I16: A | K16: PALETTE | L16: B | N16: Jordan | O16: 200cm | P16: A | R16: Lustre | S16: 240cm | T16: C
... B24: FLORENCE | C24: A | E24: Sienna | F24: A | H24: CHARM | I24: B | K24: PITCH | L24: E | N24: Origin BO | O24: 200cm | P24: A | R24: Winnow | S24: 280cm | T24: E + 10%
B25: FUSE | C25: C | E25: Surface | F25: AA | H25: CHARM B/OUT | I25: E | K25: POLARIS | L25: A | N25: Polaris | O25: 200cm | P25: B | R25: Note: All Mirage blinds will be made using Louvolite system
B26: GLITZ | C26: C | E26: Vapour | F26: A | H26: CHESTER | I26: E | K26: POLARIS B/OUT | L26: B | N26: Polaris BO | O26: 200cm | P26: C
B27: GRAYSON | C27: A | E27: Wave | F27: AA | H27: CHINDI B/OUT | I27: E | K27: RADIANCE ASC | L27: E | N27: Rannoch | O27: 200cm | P27: B
B28: IMPASTO | C28: E | H28: CORSICA | I28: B | K28: REFLECTION | L28: B | N28: Shannon | O28: 200cm | P28: A
B29: JUDE | C29: A | H29: COURTNEY | I29: C | K29: RIBBONS ASC | L29: D | N29: Sienna | O29: 200cm | P29: A
B30: LAGAN ASC | C30: C | H30: CUBIK | I30: C | K30: RONDA | L30: E | N30: Soho | O30: 198cm | P30: C
B31: LINENWEAVE | C31: B | H31: DREAMY | I31: E | K31: RONNIE | L31: E | N31: Soho BO | O31: 198cm | P31: D
B32: LIVIA ASC | C32: C | H32: ELEGANCE | I32: E | K32: RUMIE | L32: E | N32: Tay | O32: 200cm | P32: B
B33: LOTUS | C33: A | H33: ELEGANCE B/OUT | I33: E | K33: RUPERT | L33: E | N33: Tribeca | O33: 198cm | P33: C
B34: MAREA | C34: A | H34: ELLIOT | I34: E | K34: SHANTUNG | L34: B | N34: Vapour | O34: 200cm | P34: A
B35: MIYA | C35: A | H35: ELSIE | I35: E | K35: SHONA | L35: E
B36: NORDIC ASC | C36: C | H36: EMELINA | I36: E | K36: STELLA | L36: B
B37: OAKLEY | C37: A | H37: EUAN | I37: E | K37: STRATA ASC | L37: D
B38: ODESSA | C38: A | H38: EVITA | I38: A | K38: STRATFORD | L38: A
B39: PALETTE | C39: B | H39: FELIX ASC | I39: E | K39: TENNESSEE | L39: E
B40: PANACHE | C40: C | H40: FLORENCE | I40: A | K40: TESSA B/OUT | L40: E
B41: PANIER ASC | C41: B | H41: FLORENCE B/OUT | I41: D | K41: TOPAZ | L41: C
B42: PARIS | C42: D | H42: FUSCHIA SWINGTIME B/OUT | I42: E | K42: TOPSY | L42: E
B43: PERRIE | C43: A | H43: FUSE | I43: E | K43: URBAN | L43: B
B44: PIPER | C44: C | H44: GLITZ | I44: D | K44: VALIZE | L44: E
B45: POLARIS | C45: A | H45: IMPASTO | I45: E | K45: VAULT | L45: E
B46: POLARIS BLACKOUT | C46: B | H46: JAX | I46: E | K46: VERA | L46: D
... B51: RONDA | C51: D | H51: KENT | I51: F + 10% | K51: ZENITH | L51: E
B52: SHANTUNG | C52: A | H52: KYLEN | I52: C
B53: SHONA | C53: E | H53: LAGAN ASC | I53: D
...

Sheet Pleated Fabric
B2: Pleated - Cellular Ranges 2026
B3: AP - CELLEX | F3: LINESCH
B4: Range | C4: Width | D4: Band | F4: Range | G4: Width | H4: Band
B5: Daylight | C5: 3000 | D5: A | F5: Ivrea | G5: 2500 | H5: A
B6: Blackout | C6: 3000 | D6: B | F6: Ivrea Blackout | G6: 2500 | H6: B
B7: Waterproof Daylight | C7: 3000 | D7: C
B8: Waterproof Blackout | C8: 3000 | D8: C
B9: Pattern Daylight Deco | C9: 3000 | D9: B
B10: Pattern Daylight Premier | C10: 3000 | D10: B
B11: Pattern Blackout Deco | C11: 3000 | D11: B
B12: Pattern Blackout Premier | C12: 3000 | D12: B

Sheet Vertical
BB1: VERTICAL BLINDS TRADE PRICE LIST 2026 EX VAT - DISCOUNTED PRICE
B2: VERTICAL BLINDS TRADE PRICE LIST 2026 EX VAT - LIST PRICE
AZ4: Discount | BA4: ='Master Control'!C11 -> 0.35
B6: AA | C6: mm | D6: 500 | E6: 600 | F6: 700 | G6: 800 | H6: 900 | I6: 1000 | J6: 1100 | K6: 1200 | L6: 1300 | M6: 1400 | N6: 1500 | O6: 1600 | P6: 1700 | Q6: 1800 | R6: 1900 | S6: 2000 | T6: 2100 | U6: 2200 | V6: 2300 | W6: 2400 | X6: 2500 | Y6: 2600 | Z6: 2700 | AA6: 2800 | AB6: 2900 | AC6: 3000 | AD6: 3100 | AE6: 3200 | AF6: 3300 | AG6: 3400 | AH6: 3500 | AI6: 3600 | AJ6: 3700 | AK6: 3800 | AL6: 3900 | AM6: 4000 | AN6: 4100 | AO6: 4200 | AP6: 4300 | AQ6: 4400 | AR6: 4500 | AS6: 4600 | AT6: 4700 | AU6: 4800 | AV6: 4900 | AW6: 5000 | AZ6: AA | BA6: mm | BB6: 500 | BC6: 600 | BD6: 700 | BE6: 800 | BF6: 900 | BG6: 1000 | BH6: 1100 | BI6: 1200 | BJ6: 1300 | BK6: 1400 | BL6: 1500 | BM6: 1600 | BN6: 1700 | BO6: 1800 | BP6: 1900 | BQ6: 2000 | BR6: 2100 | BS6: 2200 | BT6: 2300 | BU6: 2400 | BV6: 2500 | BW6: 2600 | BX6: 2700 | BY6: 2800 | BZ6: 2900 | CA6: 3000 | CB6: 3100 | CC6: 3200 | CD6: 3300 | CE6: 3400 | CF6: 3500 | CG6: 3600 | CH6: 3700 | CI6: 3800 | CJ6: 3900 | CK6: 4000 | CL6: 4100 | CM6: 4200 | CN6: 4300 | CO6: 4400 | CP6: 4500 | CQ6: 4600 | CR6: 4700 | CS6: 4800 | CT6: 4900 | CU6: 5000
B7: mm | C7: inch | D7: 19 5/8 | E7: 23 5/8 | F7: 27 1/2 | G7: 31 1/2 | H7: 35 3/8 | I7: 39 3/8 | J7: 43 1/4 | K7: 47 1/4 | L7: 51 1/8 | M7: 55 1/8 | N7: 59 | O7: 63 | P7: 66 7/8 | Q7: 70 7/8 | R7: 74 3/4 | S7: 78 3/4 | T7: 82 5/8 | U7: 86 5/8 | V7: 90 1/2 | W7: 94 1/2 | X7: 98 3/8 | Y7: 102 3/8 | Z7: 106 1/4 | AA7: 110 1/4 | AB7: 114 1/8 | AC7: 118 1/8 | AD7: 122 | AE7: 126 | AF7: 129 7/8 | AG7: 133 7/8 | AH7: 137 3/4 | AI7: 141 3/4 | AJ7: 145 5/8 | AK7: 149 5/8 | AL7: 153 1/2 | AM7: 157 1/2 | AN7: 161 3/8 | AO7: 165 3/8 | AP7: 169 1/4 | AQ7: 173 1/4 | AR7: 177 1/8 | AS7: 181 1/8 | AT7: 185 | AU7: 189 | AV7: 192 7/8 | AW7: 196 7/8 | AZ7: mm | BA7: inch | BB7: 19 5/8 | BC7: 23 5/8 | BD7: 27 1/2 | BE7: 31 1/2 | BF7: 35 3/8 | BG7: 39 3/8 | BH7: 43 1/4 | BI7: 47 1/4 | BJ7: 51 1/8 | BK7: 55 1/8 | BL7: 59 | BM7: 63 | BN7: 66 7/8 | BO7: 70 7/8 | BP7: 74 3/4 | BQ7: 78 3/4 | BR7: 82 5/8 | BS7: 86 5/8 | BT7: 90 1/2 | BU7: 94 1/2 | BV7: 98 3/8 | BW7: 102 3/8 | BX7: 106 1/4 | BY7: 110 1/4 | BZ7: 114 1/8 | CA7: 118 1/8 | CB7: 122 | CC7: 126 | CD7: 129 7/8 | CE7: 133 7/8 | CF7: 137 3/4 | CG7: 141 3/4 | CH7: 145 5/8 | CI7: 149 5/8 | CJ7: 153 1/2 | CK7: 157 1/2 | CL7: 161 3/8 | CM7: 165 3/8 | CN7: 169 1/4 | CO7: 173 1/4 | CP7: 177 1/8 | CQ7: 181 1/8 | CR7: 185 | CS7: 189 | CT7: 192 7/8 | CU7: 196 7/8
B8: 600 | C8: 23 5/8 | D8: 15.3375 | E8: 15.3375 | F8: 15.35 | G8: 15.4875 | H8: 15.75 | I8: 16.025 | J8: 17.2625 | K8: 18.5 | L8: 19.825 | M8: 21.2375 | N8: 22.6375 | O8: 23.65 | P8: 24.6625 | Q8: 25.6875 | R8: 26.7 | S8: 27.7125 | T8: 28.5875 | U8: 29.45 | V8: 30.375 | W8: 31.3625 | X8: 32.35 | Y8: 33.7125 | Z8: 35.075 | AA8: 36.25 | AB8: 37.2375 | AC8: 38.225 | AD8: 39.425 | AE8: 40.625 | AF8: 41.7125 | AG8: 42.7 | AH8: 43.675 | AI8: 44.4625 | AJ8: 45.25 | AK8: 46.325 | AL8: 47.6875 | AM8: 49.0375 | AN8: 50.225 | AO8: 51.4125 | AP8: 52.5 | AQ8: 53.4625 | AR8: 54.4375 | AS8: 55.4125 | AT8: 56.3875 | AU8: 57.3625 | AV8: 58.325 | AW8: 59.3 | AZ8: 600 | BA8: 23 5/8 | BB8: =D8*(1-$BA$4) -> 9.969375 | BC8: =E8*(1-$BA$4) -> 9.969375 | BD8: =F8*(1-$BA$4) -> 9.9775 | BE8: =G8*(1-$BA$4) -> 10.066875 | BF8: =H8*(1-$BA$4) -> 10.2375 | BG8: =I8*(1-$BA$4) -> 10.41625 | BH8: =J8*(1-$BA$4) -> 11.220625 | BI8: =K8*(1-$BA$4) -> 12.025 | ... CU8: =AW8*(1-$BA$4) -> 38.545
B9: 700 | C9: 27 1/2 | D9: 15.3375 | E9: 15.3375 | F9: 15.35 | G9: 15.5625 | H9: 16 | I9: 16.425 | J9: 17.7 | K9: 18.975 | L9: 20.3375 | M9: 21.8 | N9: 23.2625 | O9: 24.3125 | P9: 25.3625 | Q9: 26.4125 | R9: 27.4625 | S9: 28.5125 | T9: 29.4 | U9: 30.3 | V9: 31.25 | W9: 32.275 | X9: 33.2875 | Y9: 34.7 | Z9: 36.125 | AA9: 37.3375 | AB9: 38.3625 | AC9: 39.3875 | AD9: 40.6125 | AE9: 41.85 | AF9: 42.975 | AG9: 43.9875 | AH9: 45.0125 | AI9: 45.825 | AJ9: 46.65 | AK9: 47.7625 | AL9: 49.1625 | AM9: 50.575 | AN9: 51.7875 | AO9: 53.0125 | AP9: 54.125 | AQ9: 55.1375 | AR9: 56.1375 | AS9: 57.15 | AT9: 58.15 | AU9: 59.1625 | AV9: 60.1625 | AW9: 61.175 | AZ9: 700 | BA9: 27 1/2 | BB9: =D9*(1-$BA$4) -> 9.969375 | BC9: =E9*(1-$BA$4) -> 9.969375 | BD9: =F9*(1-$BA$4) -> 9.9775 | BE9: =G9*(1-$BA$4) -> 10.115625 | BF9: =H9*(1-$BA$4) -> 10.4 | BG9: =I9*(1-$BA$4) -> 10.67625 | BH9: =J9*(1-$BA$4) -> 11.505 | BI9: =K9*(1-$BA$4) -> 12.33375 | ... CU9: =AW9*(1-$BA$4) -> 39.76375
B10: 800 | C10: 31 1/2 | D10: 15.3375 | E10: 15.3375 | F10: 15.35 | G10: 15.65 | H10: 16.2375 | I10: 16.825 | J10: 18.1375 | K10: 19.45 | L10: 20.8625 | M10: 22.375 | N10: 23.8875 | O10: 24.9625 | P10: 26.05 | Q10: 27.1375 | R10: 28.225 | S10: 29.3125 | T10: 30.225 | U10: 31.1375 | V10: 32.125 | W10: 33.175 | X10: 34.225 | Y10: 35.7 | Z10: 37.1625 | AA10: 38.425 | AB10: 39.4875 | AC10: 40.5375 | AD10: 41.8 | AE10: 43.0625 | AF10: 44.225 | AG10: 45.2875 | AH10: 46.3375 | AI10: 47.1875 | AJ10: 48.0375 | AK10: 49.1875 | AL10: 50.65 | AM10: 52.1 | AN10: 53.35 | AO10: 54.6125 | AP10: 55.7625 | AQ10: 56.8 | AR10: 57.8375 | AS10: 58.875 | AT10: 59.9125 | AU10: 60.9625 | AV10: 62 | AW10: 63.05 | AZ10: 800 | BA10: 31 1/2 | BB10: =D10*(1-$BA$4) -> 9.969375 | BC10: =E10*(1-$BA$4) -> 9.969375 | BD10: =F10*(1-$BA$4) -> 9.9775 | BE10: =G10*(1-$BA$4) -> 10.1725 | BF10: =H10*(1-$BA$4) -> 10.554375 | BG10: =I10*(1-$BA$4) -> 10.93625 | BH10: =J10*(1-$BA$4) -> 11.789375 | BI10: =K10*(1-$BA$4) -> 12.6425 | ... CU10: =AW10*(1-$BA$4) -> 40.9825
B11: 900 | C11: 35 3/8 | D11: 15.3375 | E11: 15.3375 | F11: 15.35 | G11: 15.725 | H11: 16.475 | I11: 17.225 | J11: 18.575 | K11: 19.9125 | L11: 21.375 | M11: 22.9375 | N11: 24.5125 | O11: 25.625 | P11: 26.7375 | Q11: 27.8625 | R11: 28.9875 | S11: 30.1125 | T11: 31.05 | U11: 31.9875 | V11: 33 | W11: 34.0875 | X11: 35.175 | Y11: 36.7 | Z11: 38.225 | AA11: 39.525 | AB11: 40.6125 | AC11: 41.7 | AD11: 43 | AE11: 44.3 | AF11: 45.5 | AG11: 46.5875 | AH11: 47.675 | AI11: 48.55 | AJ11: 49.425 | AK11: 50.6125 | AL11: 52.125 | AM11: 53.6375 | AN11: 54.925 | AO11: 56.2125 | AP11: 57.4 | AQ11: 58.475 | AR11: 59.55 | AS11: 60.6125 | AT11: 61.6875 | AU11: 62.7625 | AV11: 63.8375 | AW11: 64.9125 | AZ11: 900 | BA11: 35 3/8 | BB11: =D11*(1-$BA$4) -> 9.969375 | BC11: =E11*(1-$BA$4) -> 9.969375 | BD11: =F11*(1-$BA$4) -> 9.9775 | BE11: =G11*(1-$BA$4) -> 10.22125 | BF11: =H11*(1-$BA$4) -> 10.70875 | BG11: =I11*(1-$BA$4) -> 11.19625 | BH11: =J11*(1-$BA$4) -> 12.07375 | BI11: =K11*(1-$BA$4) -> 12.943125 | ... CU11: =AW11*(1-$BA$4) -> 42.193125
B12: 1000 | C12: 39 3/8 | D12: 15.3375 | E12: 15.3375 | F12: 15.35 | G12: 15.8 | H12: 16.7125 | I12: 17.625 | J12: 19 | K12: 20.3875 | L12: 21.8875 | M12: 23.5 | N12: 25.125 | O12: 26.275 | P12: 27.4375 | Q12: 28.5875 | R12: 29.75 | S12: 30.9 | T12: 31.875 | U12: 32.8375 | V12: 33.8875 | W12: 35 | X12: 36.125 | Y12: 37.7 | Z12: 39.275 | AA12: 40.625 | AB12: 41.7375 | AC12: 42.85 | AD12: 44.2 | AE12: 45.5375 | AF12: 46.775 | AG12: 47.8875 | AH12: 49 | AI12: 49.9 | AJ12: 50.8 | AK12: 52.0375 | AL12: 53.6 | AM12: 55.1625 | AN12: 56.4875 | AO12: 57.8125 | AP12: 59.025 | AQ12: 60.1375 | AR12: 61.25 | AS12: 62.35 | AT12: 63.4625 | AU12: 64.5625 | AV12: 65.675 | AW12: 66.775 | AZ12: 1000 | BA12: 39 3/8 | BB12: =D12*(1-$BA$4) -> 9.969375 | BC12: =E12*(1-$BA$4) -> 9.969375 | BD12: =F12*(1-$BA$4) -> 9.9775 | BE12: =G12*(1-$BA$4) -> 10.27 | BF12: =H12*(1-$BA$4) -> 10.863125 | BG12: =I12*(1-$BA$4) -> 11.45625 | BH12: =J12*(1-$BA$4) -> 12.35 | BI12: =K12*(1-$BA$4) -> 13.251875 | ... CU12: =AW12*(1-$BA$4) -> 43.40375
B13: 1100 | C13: 43 1/4 | D13: 15.3375 | E13: 15.3375 | F13: 15.35 | G13: 15.8875 | H13: 16.95 | I13: 18.025 | J13: 19.4375 | K13: 20.85 | L13: 22.4 | M13: 24.075 | N13: 25.75 | O13: 26.9375 | P13: 28.125 | Q13: 29.3125 | R13: 30.5125 | S13: 31.7 | T13: 32.6875 | U13: 33.6875 | V13: 34.7625 | W13: 35.9125 | X13: 37.0625 | Y13: 38.6875 | Z13: 40.3125 | AA13: 41.7125 | AB13: 42.8625 | AC13: 44.0125 | AD13: 45.3875 | AE13: 46.7625 | AF13: 48.025 | AG13: 49.175 | AH13: 50.3375 | AI13: 51.2625 | AJ13: 52.2 | AK13: 53.475 | AL13: 55.0875 | AM13: 56.7 | AN13: 58.05 | AO13: 59.4125 | AP13: 60.6625 | AQ13: 61.8 | AR13: 62.95 | AS13: 64.0875 | AT13: 65.225 | AU13: 66.3625 | AV13: 67.5125 | AW13: 68.65 | AZ13: 1100 | BA13: 43 1/4 | BB13: =D13*(1-$BA$4) -> 9.969375 | BC13: =E13*(1-$BA$4) -> 9.969375 | BD13: =F13*(1-$BA$4) -> 9.9775 | BE13: =G13*(1-$BA$4) -> 10.326875 | BF13: =H13*(1-$BA$4) -> 11.0175 | BG13: =I13*(1-$BA$4) -> 11.71625 | BH13: =J13*(1-$BA$4) -> 12.634375 | BI13: =K13*(1-$BA$4) -> 13.5525 | ... CU13: =AW13*(1-$BA$4) -> 44.6225
B14: 1200 | C14: 47 1/4 | D14: 15.3375 | E14: 15.3375 | F14: 15.35 | G14: 15.9625 | H14: 17.2 | I14: 18.425 | J14: 19.875 | K14: 21.325 | L14: 22.9125 | M14: 24.65 | N14: 26.375 | O14: 27.6 | P14: 28.8125 | Q14: 30.0375 | R14: 31.275 | S14: 32.5 | T14: 33.5125 | U14: 34.525 | V14: 35.625 | W14: 36.8125 | X14: 38 | Y14: 39.675 | Z14: 41.3625 | AA14: 42.8 | AB14: 43.9875 | AC14: 45.175 | AD14: 46.575 | AE14: 47.9875 | AF14: 49.2875 | AG14: 50.475 | AH14: 51.6625 | AI14: 52.625 | AJ14: 53.5875 | AK14: 54.9 | AL14: 56.5625 | AM14: 58.225 | AN14: 59.6125 | AO14: 61 | AP14: 62.2875 | AQ14: 63.4625 | AR14: 64.6375 | AS14: 65.8125 | AT14: 66.9875 | AU14: 68.1625 | AV14: 69.35 | AW14: 70.525 | AZ14: 1200 | BA14: 47 1/4 | BB14: =D14*(1-$BA$4) -> 9.969375 | BC14: =E14*(1-$BA$4) -> 9.969375 | BD14: =F14*(1-$BA$4) -> 9.9775 | BE14: =G14*(1-$BA$4) -> 10.375625 | BF14: =H14*(1-$BA$4) -> 11.18 | BG14: =I14*(1-$BA$4) -> 11.97625 | BH14: =J14*(1-$BA$4) -> 12.91875 | BI14: =K14*(1-$BA$4) -> 13.86125 | ... CU14: =AW14*(1-$BA$4) -> 45.84125
B15: 1300 | C15: 51 1/8 | D15: 15.3375 | E15: 15.5375 | F15: 15.7375 | G15: 16.475 | H15: 17.75 | I15: 19.0125 | J15: 20.5 | K15: 21.9875 | L15: 23.6125 | M15: 25.4 | N15: 27.1875 | O15: 28.4375 | P15: 29.6875 | Q15: 30.95 | R15: 32.225 | S15: 33.4875 | T15: 34.525 | U15: 35.5625 | V15: 36.6875 | W15: 37.9125 | X15: 39.1375 | Y15: 40.8625 | Z15: 42.5875 | AA15: 44.075 | AB15: 45.3 | AC15: 46.525 | AD15: 47.9625 | AE15: 49.4 | AF15: 50.725 | AG15: 51.95 | AH15: 53.175 | AI15: 54.1625 | AJ15: 55.1625 | AK15: 56.5125 | AL15: 58.225 | AM15: 59.9375 | AN15: 61.3625 | AO15: 62.7875 | AP15: 64.1 | AQ15: 65.3125 | AR15: 66.525 | AS15: 67.725 | AT15: 68.9375 | AU15: 70.15 | AV15: 71.3625 | AW15: 72.575 | AZ15: 1300 | BA15: 51 1/8 | BB15: =D15*(1-$BA$4) -> 9.969375 | BC15: =E15*(1-$BA$4) -> 10.099375 | BD15: =F15*(1-$BA$4) -> 10.229375 | BE15: =G15*(1-$BA$4) -> 10.70875 | BF15: =H15*(1-$BA$4) -> 11.5375 | BG15: =I15*(1-$BA$4) -> 12.358125 | BH15: =J15*(1-$BA$4) -> 13.325 | BI15: =K15*(1-$BA$4) -> 14.291875 | ... CU15: =AW15*(1-$BA$4) -> 47.17375
B16: 1400 | C16: 55 1/8 | D16: 15.3375 | E16: 15.7375 | F16: 16.1375 | G16: 16.9875 | H16: 18.3 | I16: 19.6 | J16: 21.125 | K16: 22.6375 | L16: 24.3125 | M16: 26.15 | N16: 27.9875 | O16: 29.275 | P16: 30.5625 | Q16: 31.8625 | R16: 33.175 | S16: 34.475 | T16: 35.525 | U16: 36.5875 | V16: 37.7375 | W16: 39 | X16: 40.2625 | Y16: 42.0375 | Z16: 43.825 | AA16: 45.3375 | AB16: 46.6 | AC16: 47.8625 | AD16: 49.3375 | AE16: 50.8125 | AF16: 52.175 | AG16: 53.425 | AH16: 54.675 | AI16: 55.7 | AJ16: 56.725 | AK16: 58.1125 | AL16: 59.875 | AM16: 61.6375 | AN16: 63.1 | AO16: 64.5625 | AP16: 65.9125 | AQ16: 67.15 | AR16: 68.4 | AS16: 69.65 | AT16: 70.8875 | AU16: 72.1375 | AV16: 73.375 | AW16: 74.625 | AZ16: 1400 | BA16: 55 1/8 | BB16: =D16*(1-$BA$4) -> 9.969375 | BC16: =E16*(1-$BA$4) -> 10.229375 | BD16: =F16*(1-$BA$4) -> 10.489375 | BE16: =G16*(1-$BA$4) -> 11.041875 | BF16: =H16*(1-$BA$4) -> 11.895 | BG16: =I16*(1-$BA$4) -> 12.74 | BH16: =J16*(1-$BA$4) -> 13.73125 | BI16: =K16*(1-$BA$4) -> 14.714375 | ... CU16: =AW16*(1-$BA$4) -> 48.50625
B17: 1500 | C17: 59 | D17: 15.3375 | E17: 15.8625 | F17: 16.3875 | G17: 17.325 | H17: 18.6625 | I17: 20 | J17: 21.55 | K17: 23.1125 | L17: 24.825 | M17: 26.7125 | N17: 28.6 | O17: 29.925 | P17: 31.25 | Q17: 32.5875 | R17: 33.925 | S17: 35.275 | T17: 36.35 | U17: 37.4375 | V17: 38.625 | W17: 39.9125 | X17: 41.2125 | Y17: 43.0375 | Z17: 44.875 | AA17: 46.4375 | AB17: 47.725 | AC17: 49.025 | AD17: 50.525 | AE17: 52.0375 | AF17: 53.4375 | AG17: 54.725 | AH17: 56.0125 | AI17: 57.0625 | AJ17: 58.1125 | AK17: 59.55 | AL17: 61.3625 | AM17: 63.175 | AN17: 64.6625 | AO17: 66.15 | AP17: 67.5375 | AQ17: 68.825 | AR17: 70.1125 | AS17: 71.3875 | AT17: 72.6625 | AU17: 73.95 | AV17: 75.225 | AW17: 76.5 | AZ17: 1500 | BA17: 59 | BB17: =D17*(1-$BA$4) -> 9.969375 | BC17: =E17*(1-$BA$4) -> 10.310625 | BD17: =F17*(1-$BA$4) -> 10.651875 | BE17: =G17*(1-$BA$4) -> 11.26125 | BF17: =H17*(1-$BA$4) -> 12.130625 | BG17: =I17*(1-$BA$4) -> 13 | BH17: =J17*(1-$BA$4) -> 14.0075 | BI17: =K17*(1-$BA$4) -> 15.023125 | ... CU17: =AW17*(1-$BA$4) -> 49.725
B18: 1600 | C18: 63 | D18: 15.3375 | E18: 15.9875 | F18: 16.65 | G18: 17.6625 | H18: 19.025 | I18: 20.3875 | J18: 21.9875 | K18: 23.575 | L18: 25.3375 | M18: 27.275 | N18: 29.2125 | O18: 30.575 | P18: 31.9375 | Q18: 33.3125 | R18: 34.6875 | S18: 36.0625 | T18: 37.175 | U18: 38.2875 | V18: 39.5 | W18: 40.8375 | X18: 42.1625 | Y18: 44.0375 | Z18: 45.925 | AA18: 47.525 | AB18: 48.85 | AC18: 50.175 | AD18: 51.7125 | AE18: 53.25 | AF18: 54.6875 | AG18: 56.025 | AH18: 57.35 | AI18: 58.425 | AJ18: 59.5125 | AK18: 60.975 | AL18: 62.8375 | AM18: 64.7 | AN18: 66.225 | AO18: 67.75 | AP18: 69.175 | AQ18: 70.4875 | AR18: 71.8125 | AS18: 73.125 | AT18: 74.4375 | AU18: 75.75 | AV18: 77.0625 | AW18: 78.375 | AZ18: 1600 | BA18: 63 | BB18: =D18*(1-$BA$4) -> 9.969375 | BC18: =E18*(1-$BA$4) -> 10.391875 | BD18: =F18*(1-$BA$4) -> 10.8225 | BE18: =G18*(1-$BA$4) -> 11.480625 | BF18: =H18*(1-$BA$4) -> 12.36625 | BG18: =I18*(1-$BA$4) -> 13.251875 | BH18: =J18*(1-$BA$4) -> 14.291875 | BI18: =K18*(1-$BA$4) -> 15.32375 | ... CU18: =AW18*(1-$BA$4) -> 50.94375
B19: 1700 | C19: 66 7/8 | D19: 15.975 | E19: 16.3875 | F19: 16.8125 | G19: 17.7125 | H19: 19.0875 | I19: 20.4625 | J19: 22.075 | K19: 23.675 | L19: 25.4625 | M19: 27.425 | N19: 29.3875 | O19: 30.7625 | P19: 32.1375 | Q19: 33.525 | R19: 34.9125 | S19: 36.3 | T19: 37.6625 | U19: 39.025 | V19: 40.3875 | W19: 41.75 | X19: 43.1125 | Y19: 45.0375 | Z19: 46.975 | AA19: 48.6125 | AB19: 49.975 | AC19: 51.3375 | AD19: 52.9125 | AE19: 54.4875 | AF19: 55.9625 | AG19: 57.325 | AH19: 58.6875 | AI19: 59.7875 | AJ19: 60.9 | AK19: 62.4125 | AL19: 64.325 | AM19: 66.2375 | AN19: 67.8 | AO19: 69.3625 | AP19: 70.8125 | AQ19: 72.1625 | AR19: 73.5125 | AS19: 74.8625 | AT19: 76.2125 | AU19: 77.55 | AV19: 78.9 | AW19: 80.25 | AZ19: 1700 | BA19: 66 7/8 | BB19: =D19*(1-$BA$4) -> 10.38375 | BC19: =E19*(1-$BA$4) -> 10.651875 | BD19: =F19*(1-$BA$4) -> 10.928125 | BE19: =G19*(1-$BA$4) -> 11.513125 | BF19: =H19*(1-$BA$4) -> 12.406875 | BG19: =I19*(1-$BA$4) -> 13.300625 | BH19: =J19*(1-$BA$4) -> 14.34875 | BI19: =K19*(1-$BA$4) -> 15.38875 | ... CU19: =AW19*(1-$BA$4) -> 52.1625
B20: 1800 | C20: 70 7/8 | D20: 16.6125 | E20: 16.7875 | F20: 16.975 | G20: 17.7625 | H20: 19.15 | I20: 20.5375 | J20: 22.1625 | K20: 23.775 | L20: 25.575 | M20: 27.5625 | N20: 29.55 | O20: 30.95 | P20: 32.3375 | Q20: 33.7375 | R20: 35.1375 | S20: 36.5375 | T20: 38.15 | U20: 39.7625 | V20: 41.2625 | W20: 42.65 | X20: 44.05 | Y20: 46.0375 | Z20: 48.025 | AA20: 49.7125 | AB20: 51.1 | AC20: 52.5 | AD20: 54.1125 | AE20: 55.725 | AF20: 57.2375 | AG20: 58.625 | AH20: 60.0125 | AI20: 61.15 | AJ20: 62.2875 | AK20: 63.8375 | AL20: 65.8 | AM20: 67.7625 | AN20: 69.3625 | AO20: 70.9625 | AP20: 72.45 | AQ20: 73.8375 | AR20: 75.2125 | AS20: 76.5875 | AT20: 77.975 | AU20: 79.35 | AV20: 80.7375 | AW20: 82.1125 | AZ20: 1800 | BA20: 70 7/8 | BB20: =D20*(1-$BA$4) -> 10.798125 | BC20: =E20*(1-$BA$4) -> 10.911875 | BD20: =F20*(1-$BA$4) -> 11.03375 | BE20: =G20*(1-$BA$4) -> 11.545625 | BF20: =H20*(1-$BA$4) -> 12.4475 | BG20: =I20*(1-$BA$4) -> 13.349375 | BH20: =J20*(1-$BA$4) -> 14.405625 | BI20: =K20*(1-$BA$4) -> 15.45375 | ... CU20: =AW20*(1-$BA$4) -> 53.373125
B21: 1900 | C21: 74 3/4 | D21: 16.6125 | E21: 16.9125 | F21: 17.2125 | G21: 18.075 | H21: 19.5 | I21: 20.9375 | J21: 22.5875 | K21: 24.2375 | L21: 26.075 | M21: 28.1125 | N21: 30.1625 | O21: 31.5875 | P21: 33.0125 | Q21: 34.4375 | R21: 35.875 | S21: 37.3 | T21: 38.95 | U21: 40.6 | V21: 42.1375 | W21: 43.5625 | X21: 45 | Y21: 47.025 | Z21: 49.0625 | AA21: 50.8 | AB21: 52.225 | AC21: 53.6625 | AD21: 55.3125 | AE21: 56.9625 | AF21: 58.4875 | AG21: 59.9125 | AH21: 61.3375 | AI21: 62.5 | AJ21: 63.675 | AK21: 65.2625 | AL21: 67.2875 | AM21: 69.3 | AN21: 70.9375 | AO21: 72.5625 | AP21: 74.0875 | AQ21: 75.5 | AR21: 76.9125 | AS21: 78.325 | AT21: 79.7375 | AU21: 81.15 | AV21: 82.575 | AW21: 83.9875 | AZ21: 1900 | BA21: 74 3/4 | BB21: =D21*(1-$BA$4) -> 10.798125 | BC21: =E21*(1-$BA$4) -> 10.993125 | BD21: =F21*(1-$BA$4) -> 11.188125 | BE21: =G21*(1-$BA$4) -> 11.74875 | BF21: =H21*(1-$BA$4) -> 12.675 | BG21: =I21*(1-$BA$4) -> 13.609375 | BH21: =J21*(1-$BA$4) -> 14.681875 | BI21: =K21*(1-$BA$4) -> 15.754375 | ... CU21: =AW21*(1-$BA$4) -> 54.591875
B22: 2000 | C22: 78 3/4 | D22: 16.6125 | E22: 17.0375 | F22: 17.45 | G22: 18.4 | H22: 19.8625 | I22: 21.325 | J22: 23 | K22: 24.6875 | L22: 26.575 | M22: 28.6625 | N22: 30.7625 | O22: 32.225 | P22: 33.6875 | Q22: 35.1375 | R22: 36.6 | S22: 38.0625 | T22: 39.75 | U22: 41.4375 | V22: 43.0125 | W22: 44.475 | X22: 45.9375 | Y22: 48.025 | Z22: 50.1125 | AA22: 51.8875 | AB22: 53.35 | AC22: 54.8125 | AD22: 56.5 | AE22: 58.1875 | AF22: 59.75 | AG22: 61.2125 | AH22: 62.6625 | AI22: 63.8625 | AJ22: 65.0625 | AK22: 66.7 | AL22: 68.7625 | AM22: 70.8375 | AN22: 72.5 | AO22: 74.1625 | AP22: 75.725 | AQ22: 77.1625 | AR22: 78.6125 | AS22: 80.0625 | AT22: 81.5 | AU22: 82.95 | AV22: 84.4125 | AW22: 85.8625 | AZ22: 2000 | BA22: 78 3/4 | BB22: =D22*(1-$BA$4) -> 10.798125 | BC22: =E22*(1-$BA$4) -> 11.074375 | BD22: =F22*(1-$BA$4) -> 11.3425 | BE22: =G22*(1-$BA$4) -> 11.96 | BF22: =H22*(1-$BA$4) -> 12.910625 | BG22: =I22*(1-$BA$4) -> 13.86125 | BH22: =J22*(1-$BA$4) -> 14.95 | BI22: =K22*(1-$BA$4) -> 16.046875 | ... CU22: =AW22*(1-$BA$4) -> 55.810625
B23: 2100 | C23: 82 5/8 | D23: 17.2625 | E23: 17.6875 | F23: 18.1125 | G23: 19.075 | H23: 20.575 | I23: 22.075 | J23: 23.7875 | K23: 25.5125 | L23: 27.4375 | M23: 29.5875 | N23: 31.725 | O23: 33.225 | P23: 34.725 | Q23: 36.2125 | R23: 37.7125 | S23: 39.2125 | T23: 40.925 | U23: 42.6375 | V23: 44.25 | W23: 45.75 | X23: 47.25 | Y23: 49.3875 | Z23: 51.525 | AA23: 53.3375 | AB23: 54.8375 | AC23: 56.3375 | AD23: 58.05 | AE23: 59.775 | AF23: 61.375 | AG23: 62.875 | AH23: 64.375 | AI23: 65.5875 | AJ23: 66.8125 | AK23: 68.475 | AL23: 70.6 | AM23: 72.725 | AN23: 74.425 | AO23: 76.125 | AP23: 77.7125 | AQ23: 79.1875 | AR23: 80.675 | AS23: 82.15 | AT23: 83.6375 | AU23: 85.125 | AV23: 86.6125 | AW23: 88.1 | AZ23: 2100 | BA23: 82 5/8 | BB23: =D23*(1-$BA$4) -> 11.220625 | BC23: =E23*(1-$BA$4) -> 11.496875 | BD23: =F23*(1-$BA$4) -> 11.773125 | BE23: =G23*(1-$BA$4) -> 12.39875 | BF23: =H23*(1-$BA$4) -> 13.37375 | BG23: =I23*(1-$BA$4) -> 14.34875 | BH23: =J23*(1-$BA$4) -> 15.461875 | BI23: =K23*(1-$BA$4) -> 16.583125 | ... CU23: =AW23*(1-$BA$4) -> 57.265
B24: 2200 | C24: 86 5/8 | D24: 17.9 | E24: 18.3375 | F24: 18.775 | G24: 19.75 | H24: 21.2875 | I24: 22.825 | J24: 24.575 | K24: 26.3375 | L24: 28.3125 | M24: 30.5 | N24: 32.6875 | O24: 34.225 | P24: 35.7625 | Q24: 37.2875 | R24: 38.825 | S24: 40.35 | T24: 42.1 | U24: 43.8375 | V24: 45.475 | W24: 47.0125 | X24: 48.55 | Y24: 50.7375 | Z24: 52.925 | AA24: 54.7875 | AB24: 56.325 | AC24: 57.8625 | AD24: 59.6125 | AE24: 61.3625 | AF24: 63 | AG24: 64.5375 | AH24: 66.075 | AI24: 67.3125 | AJ24: 68.55 | AK24: 70.2625 | AL24: 72.425 | AM24: 74.6 | AN24: 76.3375 | AO24: 78.075 | AP24: 79.7 | AQ24: 81.2125 | AR24: 82.7375 | AS24: 84.25 | AT24: 85.7625 | AU24: 87.2875 | AV24: 88.8 | AW24: 90.325 | AZ24: 2200 | BA24: 86 5/8 | BB24: =D24*(1-$BA$4) -> 11.635 | BC24: =E24*(1-$BA$4) -> 11.919375 | BD24: =F24*(1-$BA$4) -> 12.20375 | BE24: =G24*(1-$BA$4) -> 12.8375 | BF24: =H24*(1-$BA$4) -> 13.836875 | BG24: =I24*(1-$BA$4) -> 14.83625 | BH24: =J24*(1-$BA$4) -> 15.97375 | BI24: =K24*(1-$BA$4) -> 17.119375 | ... CU24: =AW24*(1-$BA$4) -> 58.71125
B25: 2300 | C25: 90 1/2 | D25: 17.9 | E25: 18.4625 | F25: 19.0125 | G25: 20.075 | H25: 21.65 | I25: 23.2125 | J25: 25 | K25: 26.7875 | L25: 28.8 | M25: 31.0375 | N25: 33.2875 | O25: 34.85 | P25: 36.425 | Q25: 37.9875 | R25: 39.55 | S25: 41.125 | T25: 42.9 | U25: 44.6875 | V25: 46.3625 | W25: 47.925 | X25: 49.5 | Y25: 51.75 | Z25: 53.9875 | AA25: 55.9 | AB25: 57.4625 | AC25: 59.025 | AD25: 60.8125 | AE25: 62.6 | AF25: 64.275 | AG25: 65.8375 | AH25: 67.4 | AI25: 68.675 | AJ25: 69.95 | AK25: 71.6875 | AL25: 73.9125 | AM25: 76.1375 | AN25: 77.9 | AO25: 79.6625 | AP25: 81.325 | AQ25: 82.8875 | AR25: 84.45 | AS25: 85.9875 | AT25: 87.5375 | AU25: 89.0875 | AV25: 90.6375 | AW25: 92.1875 | AZ25: 2300 | BA25: 90 1/2 | BB25: =D25*(1-$BA$4) -> 11.635 | BC25: =E25*(1-$BA$4) -> 12.000625 | BD25: =F25*(1-$BA$4) -> 12.358125 | BE25: =G25*(1-$BA$4) -> 13.04875 | BF25: =H25*(1-$BA$4) -> 14.0725 | BG25: =I25*(1-$BA$4) -> 15.088125 | BH25: =J25*(1-$BA$4) -> 16.25 | BI25: =K25*(1-$BA$4) -> 17.411875 | ... CU25: =AW25*(1-$BA$4) -> 59.921875
B26: 2400 | C26: 94 1/2 | D26: 17.9 | E26: 18.575 | F26: 19.2625 | G26: 20.4 | H26: 22 | I26: 23.6 | J26: 25.425 | K26: 27.2375 | L26: 29.3 | M26: 31.5875 | N26: 33.875 | O26: 35.475 | P26: 37.0875 | Q26: 38.6875 | R26: 40.2875 | S26: 41.8875 | T26: 43.7125 | U26: 45.525 | V26: 47.2375 | W26: 48.85 | X26: 50.45 | Y26: 52.75 | Z26: 55.05 | AA26: 57 | AB26: 58.5875 | AC26: 60.175 | AD26: 62 | AE26: 63.825 | AF26: 65.5375 | AG26: 67.125 | AH26: 68.725 | AI26: 70.025 | AJ26: 71.3375 | AK26: 73.125 | AL26: 75.3875 | AM26: 77.6625 | AN26: 79.4625 | AO26: 81.2625 | AP26: 82.9625 | AQ26: 84.55 | AR26: 86.15 | AS26: 87.725 | AT26: 89.3125 | AU26: 90.8875 | AV26: 92.475 | AW26: 94.05 | AZ26: 2400 | BA26: 94 1/2 | BB26: =D26*(1-$BA$4) -> 11.635 | BC26: =E26*(1-$BA$4) -> 12.07375 | BD26: =F26*(1-$BA$4) -> 12.520625 | BE26: =G26*(1-$BA$4) -> 13.26 | BF26: =H26*(1-$BA$4) -> 14.3 | BG26: =I26*(1-$BA$4) -> 15.34 | BH26: =J26*(1-$BA$4) -> 16.52625 | BI26: =K26*(1-$BA$4) -> 17.704375 | ... CU26: =AW26*(1-$BA$4) -> 61.1325
B27: 2500 | C27: 98 3/8 | D27: 18.5375 | E27: 19.0375 | F27: 19.5375 | G27: 20.6125 | H27: 22.2375 | I27: 23.8625 | J27: 25.7 | K27: 27.55 | L27: 29.6375 | M27: 31.975 | N27: 34.3 | O27: 35.925 | P27: 37.5625 | Q27: 39.1875 | R27: 40.8125 | S27: 42.4375 | T27: 44.275 | U27: 46.125 | V27: 47.8625 | W27: 49.4875 | X27: 51.125 | Y27: 53.4625 | Z27: 55.8 | AA27: 57.775 | AB27: 59.4 | AC27: 61.025 | AD27: 62.8625 | AE27: 64.7125 | AF27: 66.45 | AG27: 68.075 | AH27: 69.7 | AI27: 71.175 | AJ27: 72.65 | AK27: 74.55 | AL27: 76.875 | AM27: 79.2 | AN27: 81.0375 | AO27: 82.8625 | AP27: 84.5875 | AQ27: 86.2125 | AR27: 87.8375 | AS27: 89.45 | AT27: 91.075 | AU27: 92.6875 | AV27: 94.3125 | AW27: 95.925 | AZ27: 2500 | BA27: 98 3/8 | BB27: =D27*(1-$BA$4) -> 12.049375 | BC27: =E27*(1-$BA$4) -> 12.374375 | BD27: =F27*(1-$BA$4) -> 12.699375 | BE27: =G27*(1-$BA$4) -> 13.398125 | BF27: =H27*(1-$BA$4) -> 14.454375 | BG27: =I27*(1-$BA$4) -> 15.510625 | BH27: =J27*(1-$BA$4) -> 16.705 | BI27: =K27*(1-$BA$4) -> 17.9075 | ... CU27: =AW27*(1-$BA$4) -> 62.35125
B28: 2600 | C28: 102 3/8 | D28: 19.175 | E28: 19.5 | F28: 19.825 | G28: 20.8125 | H28: 22.4625 | I28: 24.1125 | J28: 25.9875 | K28: 27.8625 | L28: 29.9875 | M28: 32.35 | N28: 34.725 | O28: 36.375 | P28: 38.0375 | Q28: 39.6875 | R28: 41.3375 | S28: 42.9875 | T28: 44.85 | U28: 46.7125 | V28: 48.475 | W28: 50.1375 | X28: 51.7875 | Y28: 54.1625 | Z28: 56.5375 | AA28: 58.55 | AB28: 60.2125 | AC28: 61.8625 | AD28: 63.7375 | AE28: 65.6 | AF28: 67.3625 | AG28: 69.0125 | AH28: 70.6625 | AI28: 72.3125 | AJ28: 73.975 | AK28: 75.9875 | AL28: 78.3625 | AM28: 80.7375 | AN28: 82.6 | AO28: 84.4625 | AP28: 86.225 | AQ28: 87.875 | AR28: 89.525 | AS28: 91.175 | AT28: 92.8375 | AU28: 94.4875 | AV28: 96.15 | AW28: 97.8 | AZ28: 2600 | BA28: 102 3/8 | BB28: =D28*(1-$BA$4) -> 12.46375 | BC28: =E28*(1-$BA$4) -> 12.675 | BD28: =F28*(1-$BA$4) -> 12.88625 | BE28: =G28*(1-$BA$4) -> 13.528125 | BF28: =H28*(1-$BA$4) -> 14.600625 | BG28: =I28*(1-$BA$4) -> 15.673125 | BH28: =J28*(1-$BA$4) -> 16.891875 | BI28: =K28*(1-$BA$4) -> 18.110625 | ... CU28: =AW28*(1-$BA$4) -> 63.57
B29: 2700 | C29: 106 1/4 | D29: 19.175 | E29: 19.6125 | F29: 20.0625 | G29: 21.125 | H29: 22.8125 | I29: 24.5 | J29: 26.4 | K29: 28.3125 | L29: 30.475 | M29: 32.9 | N29: 35.325 | O29: 37.0125 | P29: 38.7 | Q29: 40.3875 | R29: 42.075 | S29: 43.7625 | T29: 45.6625 | U29: 47.5625 | V29: 49.35 | W29: 51.0375 | X29: 52.7375 | Y29: 55.15 | Z29: 57.575 | AA29: 59.6375 | AB29: 61.325 | AC29: 63.0125 | AD29: 64.9125 | AE29: 66.8125 | AF29: 68.6125 | AG29: 70.3 | AH29: 71.9875 | AI29: 73.675 | AJ29: 75.3625 | AK29: 77.425 | AL29: 79.85 | AM29: 82.275 | AN29: 84.175 | AO29: 86.075 | AP29: 87.8625 | AQ29: 89.5375 | AR29: 91.225 | AS29: 92.9125 | AT29: 94.6125 | AU29: 96.3 | AV29: 97.975 | AW29: 99.6625 | AZ29: 2700 | BA29: 106 1/4 | BB29: =D29*(1-$BA$4) -> 12.46375 | BC29: =E29*(1-$BA$4) -> 12.748125 | BD29: =F29*(1-$BA$4) -> 13.040625 | BE29: =G29*(1-$BA$4) -> 13.73125 | BF29: =H29*(1-$BA$4) -> 14.828125 | BG29: =I29*(1-$BA$4) -> 15.925 | BH29: =J29*(1-$BA$4) -> 17.16 | BI29: =K29*(1-$BA$4) -> 18.403125 | ... CU29: =AW29*(1-$BA$4) -> 64.780625
B30: 2800 | C30: 110 1/4 | D30: 19.175 | E30: 19.7375 | F30: 20.3 | G30: 21.4375 | H30: 23.1625 | I30: 24.8875 | J30: 26.825 | K30: 28.7625 | L30: 30.9625 | M30: 33.4375 | N30: 35.9125 | O30: 37.6375 | P30: 39.3625 | Q30: 41.0875 | R30: 42.8 | S30: 44.525 | T30: 46.4625 | U30: 48.4 | V30: 50.225 | W30: 51.95 | X30: 53.675 | Y30: 56.15 | Z30: 58.6125 | AA30: 60.7125 | AB30: 62.425 | AC30: 64.15 | AD30: 66.0875 | AE30: 68.025 | AF30: 69.85 | AG30: 71.575 | AH30: 73.3 | AI30: 75.025 | AJ30: 76.75 | AK30: 78.85 | AL30: 81.325 | AM30: 83.8 | AN30: 85.7375 | AO30: 87.675 | AP30: 89.5 | AQ30: 91.2125 | AR30: 92.925 | AS30: 94.65 | AT30: 96.3875 | AU30: 98.1 | AV30: 99.8125 | AW30: 101.525 | AZ30: 2800 | BA30: 110 1/4 | BB30: =D30*(1-$BA$4) -> 12.46375 | BC30: =E30*(1-$BA$4) -> 12.829375 | BD30: =F30*(1-$BA$4) -> 13.195 | BE30: =G30*(1-$BA$4) -> 13.934375 | BF30: =H30*(1-$BA$4) -> 15.055625 | BG30: =I30*(1-$BA$4) -> 16.176875 | BH30: =J30*(1-$BA$4) -> 17.43625 | BI30: =K30*(1-$BA$4) -> 18.695625 | ... CU30: =AW30*(1-$BA$4) -> 65.99125
... B32: 3000 | C32: 118 1/8 | D32: 20.45 | E32: 20.75 | F32: 21.0375 | G32: 22.075 | H32: 23.8625 | I32: 25.65 | J32: 27.65 | K32: 29.65 | L32: 31.9375 | M32: 34.5125 | N32: 37.0875 | O32: 38.8875 | P32: 40.675 | Q32: 42.475 | R32: 44.2625 | S32: 46.05 | T32: 48.05 | U32: 50.0625 | V32: 51.95 | W32: 53.7375 | X32: 55.525 | Y32: 58.1125 | Z32: 60.7 | AA32: 62.8875 | AB32: 64.675 | AC32: 66.4625 | AD32: 68.4625 | AE32: 70.4625 | AF32: 72.3625 | AG32: 74.15 | AH32: 75.9375 | AI32: 77.725 | AJ32: 79.5125 | AK32: 81.7 | AL32: 84.275 | AM32: 86.85 | AN32: 88.85 | AO32: 90.8625 | AP32: 92.7625 | AQ32: 94.55 | AR32: 96.3375 | AS32: 98.125 | AT32: 99.9125 | AU32: 101.7 | AV32: 103.4875 | AW32: 105.275 | AZ32: 3000 | BA32: 118 1/8 | BB32: =D32*(1-$BA$4) -> 13.2925 | BC32: =E32*(1-$BA$4) -> 13.4875 | BD32: =F32*(1-$BA$4) -> 13.674375 | BE32: =G32*(1-$BA$4) -> 14.34875 | BF32: =H32*(1-$BA$4) -> 15.510625 | BG32: =I32*(1-$BA$4) -> 16.6725 | BH32: =J32*(1-$BA$4) -> 17.9725 | BI32: =K32*(1-$BA$4) -> 19.2725 | ... CU32: =AW32*(1-$BA$4) -> 68.42875
B33: 3100 | C33: 122 | D33: 20.45 | E33: 20.8625 | F33: 21.275 | G33: 22.3875 | H33: 24.2125 | I33: 26.0375 | J33: 28.075 | K33: 30.1125 | L33: 32.4375 | M33: 35.0625 | N33: 37.6875 | O33: 39.5125 | P33: 41.35 | Q33: 43.175 | R33: 45 | S33: 46.825 | T33: 48.8625 | U33: 50.9 | V33: 52.825 | W33: 54.65 | X33: 56.475 | Y33: 59.1 | Z33: 61.7375 | AA33: 63.9625 | AB33: 65.7875 | AC33: 67.6125 | AD33: 69.65 | AE33: 71.6875 | AF33: 73.6125 | AG33: 75.4375 | AH33: 77.2625 | AI33: 79.075 | AJ33: 80.9 | AK33: 83.125 | AL33: 85.75 | AM33: 88.3875 | AN33: 90.425 | AO33: 92.4625 | AP33: 94.3875 | AQ33: 96.2125 | AR33: 98.0375 | AS33: 99.8625 | AT33: 101.6875 | AU33: 103.5 | AV33: 105.325 | AW33: 107.15 | AZ33: 3100 | BA33: 122 | BB33: =D33*(1-$BA$4) -> 13.2925 | BC33: =E33*(1-$BA$4) -> 13.560625 | BD33: =F33*(1-$BA$4) -> 13.82875 | BE33: =G33*(1-$BA$4) -> 14.551875 | BF33: =H33*(1-$BA$4) -> 15.738125 | BG33: =I33*(1-$BA$4) -> 16.924375 | BH33: =J33*(1-$BA$4) -> 18.24875 | BI33: =K33*(1-$BA$4) -> 19.573125 | ... CU33: =AW33*(1-$BA$4) -> 69.6475
B34: 3200 | C34: 126 | D34: 20.45 | E34: 20.975 | F34: 21.5125 | G34: 22.7 | H34: 24.5625 | I34: 26.4125 | J34: 28.4875 | K34: 30.5625 | L34: 32.9375 | M34: 35.6 | N34: 38.275 | O34: 40.15 | P34: 42.0125 | Q34: 43.875 | R34: 45.7375 | S34: 47.5875 | T34: 49.6625 | U34: 51.725 | V34: 53.6875 | W34: 55.55 | X34: 57.4125 | Y34: 60.0875 | Z34: 62.775 | AA34: 65.0375 | AB34: 66.9 | AC34: 68.75 | AD34: 70.825 | AE34: 72.9 | AF34: 74.8625 | AG34: 76.725 | AH34: 78.575 | AI34: 80.425 | AJ34: 82.2875 | AK34: 84.55 | AL34: 87.2375 | AM34: 89.9125 | AN34: 91.9875 | AO34: 94.05 | AP34: 96.0125 | AQ34: 97.875 | AR34: 99.7375 | AS34: 101.6 | AT34: 103.4625 | AU34: 105.3125 | AV34: 107.1625 | AW34: 109.0125 | AZ34: 3200 | BA34: 126 | BB34: =D34*(1-$BA$4) -> 13.2925 | BC34: =E34*(1-$BA$4) -> 13.63375 | BD34: =F34*(1-$BA$4) -> 13.983125 | BE34: =G34*(1-$BA$4) -> 14.755 | BF34: =H34*(1-$BA$4) -> 15.965625 | BG34: =I34*(1-$BA$4) -> 17.168125 | BH34: =J34*(1-$BA$4) -> 18.516875 | BI34: =K34*(1-$BA$4) -> 19.865625 | ... CU34: =AW34*(1-$BA$4) -> 70.858125
B37: A | C37: mm | D37: 500 | E37: 600 | F37: 700 | G37: 800 | H37: 900 | I37: 1000 | J37: 1100 | K37: 1200 | L37: 1300 | M37: 1400 | N37: 1500 | O37: 1600 | P37: 1700 | Q37: 1800 | R37: 1900 | S37: 2000 | T37: 2100 | U37: 2200 | V37: 2300 | W37: 2400 | X37: 2500 | Y37: 2600 | Z37: 2700 | AA37: 2800 | AB37: 2900 | AC37: 3000 | AD37: 3100 | AE37: 3200 | AF37: 3300 | AG37: 3400 | AH37: 3500 | AI37: 3600 | AJ37: 3700 | AK37: 3800 | AL37: 3900 | AM37: 4000 | AN37: 4100 | AO37: 4200 | AP37: 4300 | AQ37: 4400 | AR37: 4500 | AS37: 4600 | AT37: 4700 | AU37: 4800 | AV37: 4900 | AW37: 5000 | AZ37: A | BA37: mm | BB37: 500 | BC37: 600 | BD37: 700 | BE37: 800 | BF37: 900 | BG37: 1000 | BH37: 1100 | BI37: 1200 | BJ37: 1300 | BK37: 1400 | BL37: 1500 | BM37: 1600 | BN37: 1700 | BO37: 1800 | BP37: 1900 | BQ37: 2000 | BR37: 2100 | BS37: 2200 | BT37: 2300 | BU37: 2400 | BV37: 2500 | BW37: 2600 | BX37: 2700 | BY37: 2800 | BZ37: 2900 | CA37: 3000 | CB37: 3100 | CC37: 3200 | CD37: 3300 | CE37: 3400 | CF37: 3500 | CG37: 3600 | CH37: 3700 | CI37: 3800 | CJ37: 3900 | CK37: 4000 | CL37: 4100 | CM37: 4200 | CN37: 4300 | CO37: 4400 | CP37: 4500 | CQ37: 4600 | CR37: 4700 | CS37: 4800 | CT37: 4900 | CU37: 5000
B38: mm | C38: inch | D38: 19 5/8 | E38: 23 5/8 | F38: 27 1/2 | G38: 31 1/2 | H38: 35 3/8 | I38: 39 3/8 | J38: 43 1/4 | K38: 47 1/4 | L38: 51 1/8 | M38: 55 1/8 | N38: 59 | O38: 63 | P38: 66 7/8 | Q38: 70 7/8 | R38: 74 3/4 | S38: 78 3/4 | T38: 82 5/8 | U38: 86 5/8 | V38: 90 1/2 | W38: 94 1/2 | X38: 98 3/8 | Y38: 102 3/8 | Z38: 106 1/4 | AA38: 110 1/4 | AB38: 114 1/8 | AC38: 118 1/8 | AD38: 122 | AE38: 126 | AF38: 129 7/8 | AG38: 133 7/8 | AH38: 137 3/4 | AI38: 141 3/4 | AJ38: 145 5/8 | AK38: 149 5/8 | AL38: 153 1/2 | AM38: 157 1/2 | AN38: 161 3/8 | AO38: 165 3/8 | AP38: 169 1/4 | AQ38: 173 1/4 | AR38: 177 1/8 | AS38: 181 1/8 | AT38: 185 | AU38: 189 | AV38: 192 7/8 | AW38: 196 7/8 | AZ38: mm | BA38: inch | BB38: 19 5/8 | BC38: 23 5/8 | BD38: 27 1/2 | BE38: 31 1/2 | BF38: 35 3/8 | BG38: 39 3/8 | BH38: 43 1/4 | BI38: 47 1/4 | BJ38: 51 1/8 | BK38: 55 1/8 | BL38: 59 | BM38: 63 | BN38: 66 7/8 | BO38: 70 7/8 | BP38: 74 3/4 | BQ38: 78 3/4 | BR38: 82 5/8 | BS38: 86 5/8 | BT38: 90 1/2 | BU38: 94 1/2 | BV38: 98 3/8 | BW38: 102 3/8 | BX38: 106 1/4 | BY38: 110 1/4 | BZ38: 114 1/8 | CA38: 118 1/8 | CB38: 122 | CC38: 126 | CD38: 129 7/8 | CE38: 133 7/8 | CF38: 137 3/4 | CG38: 141 3/4 | CH38: 145 5/8 | CI38: 149 5/8 | CJ38: 153 1/2 | CK38: 157 1/2 | CL38: 161 3/8 | CM38: 165 3/8 | CN38: 169 1/4 | CO38: 173 1/4 | CP38: 177 1/8 | CQ38: 181 1/8 | CR38: 185 | CS38: 189 | CT38: 192 7/8 | CU38: 196 7/8
B39: 600 | C39: 23 5/8 | D39: 16.7875 | E39: 16.7875 | F39: 16.7875 | G39: 16.9875 | H39: 17.375 | I39: 17.7625 | J39: 19.1375 | K39: 20.5 | L39: 21.9625 | M39: 23.525 | N39: 25.075 | O39: 26.2 | P39: 27.3375 | Q39: 28.4625 | R39: 29.575 | S39: 30.7 | T39: 31.6625 | U39: 32.625 | V39: 33.65 | W39: 34.7375 | X39: 35.825 | Y39: 37.3375 | Z39: 38.85 | AA39: 40.1625 | AB39: 41.25 | AC39: 42.3375 | AD39: 43.6625 | AE39: 45 | AF39: 46.2125 | AG39: 47.3 | AH39: 48.3875 | AI39: 49.2625 | AJ39: 50.125 | AK39: 51.3125 | AL39: 52.825 | AM39: 54.325 | AN39: 55.6375 | AO39: 56.95 | AP39: 58.15 | AQ39: 59.2375 | AR39: 60.3125 | AS39: 61.3875 | AT39: 62.4625 | AU39: 63.5375 | AV39: 64.6125 | AW39: 65.6875 | AZ39: 600 | BA39: 23 5/8 | BB39: =D39*(1-$BA$4) -> 10.911875 | BC39: =E39*(1-$BA$4) -> 10.911875 | BD39: =F39*(1-$BA$4) -> 10.911875 | BE39: =G39*(1-$BA$4) -> 11.041875 | BF39: =H39*(1-$BA$4) -> 11.29375 | BG39: =I39*(1-$BA$4) -> 11.545625 | BH39: =J39*(1-$BA$4) -> 12.439375 | BI39: =K39*(1-$BA$4) -> 13.325 | ... CU39: =AW39*(1-$BA$4) -> 42.696875
